<?xml version="1.0"?>
<robot name="zhiguli">
  
  <!-- Base Link (lower chassis) -->
  <link name="base_link">
    <visual>
      <geometry>
        <box size="1.6 0.7 0.2"/>
      </geometry>
      <material name="red">
        <color rgba="0.8 0.1 0.1 1"/>
      </material>
    </visual>
    <collision>
      <geometry>
        <box size="1.6 0.7 0.2"/>
      </geometry>
    </collision>
    <inertial>
      <mass value="80.0"/>
      <inertia ixx="10.0" ixy="0.0" ixz="0.0" iyy="40.0" iyz="0.0" izz="45.0"/>
    </inertial>
  </link>

  <!-- Hood (капот) -->
  <link name="hood">
    <visual>
      <geometry>
        <box size="0.5 0.65 0.25"/>
      </geometry>
      <material name="red">
        <color rgba="0.8 0.1 0.1 1"/>
      </material>
    </visual>
    <collision>
      <geometry>
        <box size="0.5 0.65 0.25"/>
      </geometry>
    </collision>
    <inertial>
      <mass value="15.0"/>
      <inertia ixx="1.0" ixy="0" ixz="0" iyy="2.0" iyz="0" izz="2.5"/>
    </inertial>
  </link>

  <joint name="hood_joint" type="fixed">
    <parent link="base_link"/>
    <child link="hood"/>
    <origin xyz="0.6 0 0.22" rpy="0 -0.1 0"/>
  </joint>

  <!-- Cabin (салон) -->
  <link name="cabin">
    <visual>
      <geometry>
        <box size="0.7 0.65 0.5"/>
      </geometry>
      <material name="light_blue">
        <color rgba="0.7 0.8 0.9 0.6"/>
      </material>
    </visual>
    <collision>
      <geometry>
        <box size="0.7 0.65 0.5"/>
      </geometry>
    </collision>
    <inertial>
      <mass value="20.0"/>
      <inertia ixx="2.0" ixy="0" ixz="0" iyy="3.0" iyz="0" izz="4.0"/>
    </inertial>
  </link>

  <joint name="cabin_joint" type="fixed">
    <parent link="base_link"/>
    <child link="cabin"/>
    <origin xyz="0.1 0 0.45" rpy="0 0 0"/>
  </joint>

  <!-- Roof (крыша) -->
  <link name="roof">
    <visual>
      <geometry>
        <box size="0.65 0.6 0.05"/>
      </geometry>
      <material name="red">
        <color rgba="0.8 0.1 0.1 1"/>
      </material>
    </visual>
    <collision>
      <geometry>
        <box size="0.65 0.6 0.05"/>
      </geometry>
    </collision>
    <inertial>
      <mass value="8.0"/>
      <inertia ixx="0.5" ixy="0" ixz="0" iyy="1.0" iyz="0" izz="1.2"/>
    </inertial>
  </link>

  <joint name="roof_joint" type="fixed">
    <parent link="cabin"/>
    <child link="roof"/>
    <origin xyz="0 0 0.27" rpy="0 0 0"/>
  </joint>

  <!-- Trunk (багажник) -->
  <link name="trunk">
    <visual>
      <geometry>
        <box size="0.4 0.65 0.3"/>
      </geometry>
      <material name="red">
        <color rgba="0.8 0.1 0.1 1"/>
      </material>
    </visual>
    <collision>
      <geometry>
        <box size="0.4 0.65 0.3"/>
      </geometry>
    </collision>
    <inertial>
      <mass value="12.0"/>
      <inertia ixx="1.0" ixy="0" ixz="0" iyy="1.5" iyz="0" izz="2.0"/>
    </inertial>
  </link>

  <joint name="trunk_joint" type="fixed">
    <parent link="base_link"/>
    <child link="trunk"/>
    <origin xyz="-0.6 0 0.25" rpy="0 0.05 0"/>
  </joint>

  <!-- Front Bumper (передний бампер) -->
  <link name="front_bumper">
    <visual>
      <geometry>
        <box size="0.1 0.7 0.12"/>
      </geometry>
      <material name="chrome">
        <color rgba="0.8 0.8 0.8 1"/>
      </material>
    </visual>
    <collision>
      <geometry>
        <box size="0.1 0.7 0.12"/>
      </geometry>
    </collision>
    <inertial>
      <mass value="3.0"/>
      <inertia ixx="0.1" ixy="0" ixz="0" iyy="0.2" iyz="0" izz="0.2"/>
    </inertial>
  </link>

  <joint name="front_bumper_joint" type="fixed">
    <parent link="base_link"/>
    <child link="front_bumper"/>
    <origin xyz="0.85 0 0.0" rpy="0 0 0"/>
  </joint>

  <!-- Rear Bumper (задний бампер) -->
  <link name="rear_bumper">
    <visual>
      <geometry>
        <box size="0.1 0.7 0.12"/>
      </geometry>
      <material name="chrome">
        <color rgba="0.8 0.8 0.8 1"/>
      </material>
    </visual>
    <collision>
      <geometry>
        <box size="0.1 0.7 0.12"/>
      </geometry>
    </collision>
    <inertial>
      <mass value="3.0"/>
      <inertia ixx="0.1" ixy="0" ixz="0" iyy="0.2" iyz="0" izz="0.2"/>
    </inertial>
  </link>

  <joint name="rear_bumper_joint" type="fixed">
    <parent link="base_link"/>
    <child link="rear_bumper"/>
    <origin xyz="-0.85 0 0.0" rpy="0 0 0"/>
  </joint>

  <!-- Left Front Wheel -->
  <link name="left_front_wheel">
    <visual>
      <geometry>
        <cylinder length="0.12" radius="0.18"/>
      </geometry>
      <origin rpy="1.57 0 0" xyz="0 0 0"/>
      <material name="black">
        <color rgba="0.1 0.1 0.1 1"/>
      </material>
    </visual>
    <collision>
      <geometry>
        <cylinder length="0.12" radius="0.18"/>
      </geometry>
      <origin rpy="1.57 0 0" xyz="0 0 0"/>
    </collision>
    <inertial>
      <mass value="3.0"/>
      <inertia ixx="0.08" ixy="0" ixz="0" iyy="0.08" iyz="0" izz="0.08"/>
    </inertial>
  </link>

  <joint name="left_front_wheel_joint" type="continuous">
    <parent link="base_link"/>
    <child link="left_front_wheel"/>
    <origin xyz="0.48 0.41 -0.18" rpy="0 0 0"/>
    <axis xyz="0 1 0"/>
  </joint>

  <!-- Right Front Wheel -->
  <link name="right_front_wheel">
    <visual>
      <geometry>
        <cylinder length="0.12" radius="0.18"/>
      </geometry>
      <origin rpy="1.57 0 0" xyz="0 0 0"/>
      <material name="black">
        <color rgba="0.1 0.1 0.1 1"/>
      </material>
    </visual>
    <collision>
      <geometry>
        <cylinder length="0.12" radius="0.18"/>
      </geometry>
      <origin rpy="1.57 0 0" xyz="0 0 0"/>
    </collision>
    <inertial>
      <mass value="3.0"/>
      <inertia ixx="0.08" ixy="0" ixz="0" iyy="0.08" iyz="0" izz="0.08"/>
    </inertial>
  </link>

  <joint name="right_front_wheel_joint" type="continuous">
    <parent link="base_link"/>
    <child link="right_front_wheel"/>
    <origin xyz="0.48 -0.41 -0.18" rpy="0 0 0"/>
    <axis xyz="0 1 0"/>
  </joint>

  <!-- Left Rear Wheel -->
  <link name="left_rear_wheel">
    <visual>
      <geometry>
        <cylinder length="0.12" radius="0.18"/>
      </geometry>
      <origin rpy="1.57 0 0" xyz="0 0 0"/>
      <material name="black">
        <color rgba="0.1 0.1 0.1 1"/>
      </material>
    </visual>
    <collision>
      <geometry>
        <cylinder length="0.12" radius="0.18"/>
      </geometry>
      <origin rpy="1.57 0 0" xyz="0 0 0"/>
    </collision>
    <inertial>
      <mass value="3.0"/>
      <inertia ixx="0.08" ixy="0" ixz="0" iyy="0.08" iyz="0" izz="0.08"/>
    </inertial>
  </link>

  <joint name="left_rear_wheel_joint" type="continuous">
    <parent link="base_link"/>
    <child link="left_rear_wheel"/>
    <origin xyz="-0.48 0.41 -0.18" rpy="0 0 0"/>
    <axis xyz="0 1 0"/>
  </joint>

  <!-- Right Rear Wheel -->
  <link name="right_rear_wheel">
    <visual>
      <geometry>
        <cylinder length="0.12" radius="0.18"/>
      </geometry>
      <origin rpy="1.57 0 0" xyz="0 0 0"/>
      <material name="black">
        <color rgba="0.1 0.1 0.1 1"/>
      </material>
    </visual>
    <collision>
      <geometry>
        <cylinder length="0.12" radius="0.18"/>
      </geometry>
      <origin rpy="1.57 0 0" xyz="0 0 0"/>
    </collision>
    <inertial>
      <mass value="3.0"/>
      <inertia ixx="0.08" ixy="0" ixz="0" iyy="0.08" iyz="0" izz="0.08"/>
    </inertial>
  </link>

  <joint name="right_rear_wheel_joint" type="continuous">
    <parent link="base_link"/>
    <child link="right_rear_wheel"/>
    <origin xyz="-0.48 -0.41 -0.18" rpy="0 0 0"/>
    <axis xyz="0 1 0"/>
  </joint>

  <!-- Front Lights -->
  <link name="left_headlight">
    <visual>
      <geometry>
        <cylinder length="0.05" radius="0.06"/>
      </geometry>
      <origin rpy="0 1.57 0" xyz="0 0 0"/>
      <material name="yellow">
        <color rgba="1.0 1.0 0.3 1"/>
      </material>
    </visual>
    <collision>
      <geometry>
        <cylinder length="0.05" radius="0.06"/>
      </geometry>
      <origin rpy="0 1.57 0" xyz="0 0 0"/>
    </collision>
    <inertial>
      <mass value="0.5"/>
      <inertia ixx="0.01" ixy="0" ixz="0" iyy="0.01" iyz="0" izz="0.01"/>
    </inertial>
  </link>

  <joint name="left_headlight_joint" type="fixed">
    <parent link="base_link"/>
    <child link="left_headlight"/>
    <origin xyz="0.82 0.22 0.08" rpy="0 0 0"/>
  </joint>

  <link name="right_headlight">
    <visual>
      <geometry>
        <cylinder length="0.05" radius="0.06"/>
      </geometry>
      <origin rpy="0 1.57 0" xyz="0 0 0"/>
      <material name="yellow">
        <color rgba="1.0 1.0 0.3 1"/>
      </material>
    </visual>
    <collision>
      <geometry>
        <cylinder length="0.05" radius="0.06"/>
      </geometry>
      <origin rpy="0 1.57 0" xyz="0 0 0"/>
    </collision>
    <inertial>
      <mass value="0.5"/>
      <inertia ixx="0.01" ixy="0" ixz="0" iyy="0.01" iyz="0" izz="0.01"/>
    </inertial>
  </link>

  <joint name="right_headlight_joint" type="fixed">
    <parent link="base_link"/>
    <child link="right_headlight"/>
    <origin xyz="0.82 -0.22 0.08" rpy="0 0 0"/>
  </joint>

  <!-- Rear Lights -->
  <link name="left_taillight">
    <visual>
      <geometry>
        <box size="0.03 0.1 0.08"/>
      </geometry>
      <material name="red_light">
        <color rgba="1.0 0.0 0.0 1"/>
      </material>
    </visual>
    <collision>
      <geometry>
        <box size="0.03 0.1 0.08"/>
      </geometry>
    </collision>
    <inertial>
      <mass value="0.3"/>
      <inertia ixx="0.01" ixy="0" ixz="0" iyy="0.01" iyz="0" izz="0.01"/>
    </inertial>
  </link>

  <joint name="left_taillight_joint" type="fixed">
    <parent link="base_link"/>
    <child link="left_taillight"/>
    <origin xyz="-0.82 0.26 0.12" rpy="0 0 0"/>
  </joint>

  <link name="right_taillight">
    <visual>
      <geometry>
        <box size="0.03 0.1 0.08"/>
      </geometry>
      <material name="red_light">
        <color rgba="1.0 0.0 0.0 1"/>
      </material>
    </visual>
    <collision>
      <geometry>
        <box size="0.03 0.1 0.08"/>
      </geometry>
    </collision>
    <inertial>
      <mass value="0.3"/>
      <inertia ixx="0.01" ixy="0" ixz="0" iyy="0.01" iyz="0" izz="0.01"/>
    </inertial>
  </link>

  <joint name="right_taillight_joint" type="fixed">
    <parent link="base_link"/>
    <child link="right_taillight"/>
    <origin xyz="-0.82 -0.26 0.12" rpy="0 0 0"/>
  </joint>

</robot>