<?xml version="1.0"?>
<robot name="zhiguli">
  
  <!-- Base Link (lower chassis - ВАЗ-2101 style) -->
  <link name="base_link">
    <visual>
      <geometry>
        <box size="1.8 0.65 0.12"/>
      </geometry>
      <material name="red">
        <color rgba="0.9 0.15 0.1 1"/>
      </material>
    </visual>
    <collision>
      <geometry>
        <box size="1.8 0.60 0.12"/>
      </geometry>
    </collision>
    <inertial>
      <mass value="35.0"/>
      <origin xyz="0.0 0 0" rpy="0 0 0"/>
      <inertia ixx="12.0" ixy="0.0" ixz="0.0" iyy="25.0" iyz="0.0" izz="30.0"/>
    </inertial>
  </link>

  <!-- Hood (капот - характерная форма Жигулей) -->
  <link name="hood">
    <visual>
      <geometry>
        <box size="0.55 0.62 0.08"/>
      </geometry>
      <material name="red">
        <color rgba="0.9 0.15 0.1 1"/>
      </material>
    </visual>
    <collision>
      <geometry>
        <box size="0.55 0.62 0.08"/>
      </geometry>
    </collision>
    <inertial>
      <mass value="4.0"/>
      <origin xyz="0 0 0" rpy="0 0 0"/>
      <inertia ixx="0.4" ixy="0" ixz="0" iyy="0.8" iyz="0" izz="1.0"/>
    </inertial>
  </link>

  <joint name="hood_joint" type="fixed">
    <parent link="base_link"/>
    <child link="hood"/>
    <origin xyz="0.55 0 0.1" rpy="0 0.03 0"/>
  </joint>

  <!-- Hood Ridge (выступ на капоте - характерная черта Жигулей) -->
  <link name="hood_ridge">
    <visual>
      <geometry>
        <box size="0.5 0.08 0.02"/>
      </geometry>
      <material name="red">
        <color rgba="0.9 0.15 0.1 1"/>
      </material>
    </visual>
  </link>

  <joint name="hood_ridge_joint" type="fixed">
    <parent link="hood"/>
    <child link="hood_ridge"/>
    <origin xyz="0 0 0.05" rpy="0 0 0"/>
  </joint>

  <!-- Front Fender Left (переднее крыло) -->
  <link name="front_fender_left">
    <visual>
      <geometry>
        <box size="0.45 0.08 0.18"/>
      </geometry>
      <material name="red">
        <color rgba="0.9 0.15 0.1 1"/>
      </material>
    </visual>
    <inertial>
      <mass value="2.0"/>
      <origin xyz="0 0 0" rpy="0 0 0"/>
      <inertia ixx="0.1" ixy="0" ixz="0" iyy="0.2" iyz="0" izz="0.2"/>
    </inertial>
  </link>

  <joint name="front_fender_left_joint" type="fixed">
    <parent link="base_link"/>
    <child link="front_fender_left"/>
    <origin xyz="0.5 0.36 0.03" rpy="0 0 0"/>
  </joint>

  <!-- Front Fender Right -->
  <link name="front_fender_right">
    <visual>
      <geometry>
        <box size="0.45 0.08 0.18"/>
      </geometry>
      <material name="red">
        <color rgba="0.9 0.15 0.1 1"/>
      </material>
    </visual>
    <inertial>
      <mass value="2.0"/>
      <origin xyz="0 0 0" rpy="0 0 0"/>
      <inertia ixx="0.1" ixy="0" ixz="0" iyy="0.2" iyz="0" izz="0.2"/>
    </inertial>
  </link>

  <joint name="front_fender_right_joint" type="fixed">
    <parent link="base_link"/>
    <child link="front_fender_right"/>
    <origin xyz="0.5 -0.36 0.03" rpy="0 0 0"/>
  </joint>

  <!-- Rear Fender Left (заднее крыло) -->
  <link name="rear_fender_left">
    <visual>
      <geometry>
        <box size="0.45 0.08 0.18"/>
      </geometry>
      <material name="red">
        <color rgba="0.9 0.15 0.1 1"/>
      </material>
    </visual>
    <inertial>
      <mass value="2.0"/>
      <origin xyz="0 0 0" rpy="0 0 0"/>
      <inertia ixx="0.1" ixy="0" ixz="0" iyy="0.2" iyz="0" izz="0.2"/>
    </inertial>
  </link>

  <joint name="rear_fender_left_joint" type="fixed">
    <parent link="base_link"/>
    <child link="rear_fender_left"/>
    <origin xyz="-0.5 0.36 0.03" rpy="0 0 0"/>
  </joint>

  <!-- Rear Fender Right -->
  <link name="rear_fender_right">
    <visual>
      <geometry>
        <box size="0.45 0.08 0.18"/>
      </geometry>
      <material name="red">
        <color rgba="0.9 0.15 0.1 1"/>
      </material>
    </visual>
    <inertial>
      <mass value="2.0"/>
      <origin xyz="0 0 0" rpy="0 0 0"/>
      <inertia ixx="0.1" ixy="0" ixz="0" iyy="0.2" iyz="0" izz="0.2"/>
    </inertial>
  </link>

  <joint name="rear_fender_right_joint" type="fixed">
    <parent link="base_link"/>
    <child link="rear_fender_right"/>
    <origin xyz="-0.5 -0.36 0.03" rpy="0 0 0"/>
  </joint>

  <!-- Cabin (кабина - классическая форма ВАЗ-2101) -->
  <link name="cabin">
    <visual>
      <geometry>
        <box size="0.75 0.6 0.32"/>
      </geometry>
      <material name="light_blue">
        <color rgba="0.7 0.85 0.95 0.7"/>
      </material>
    </visual>
    <collision>
      <geometry>
        <box size="0.75 0.6 0.32"/>
      </geometry>
    </collision>
    <inertial>
      <mass value="8.0"/>
      <origin xyz="0 0 0" rpy="0 0 0"/>
      <inertia ixx="1.0" ixy="0" ixz="0" iyy="1.5" iyz="0" izz="2.0"/>
    </inertial>
  </link>

  <joint name="cabin_joint" type="fixed">
    <parent link="base_link"/>
    <child link="cabin"/>
    <origin xyz="-0.05 0 0.22" rpy="0 0 0"/>
  </joint>

  <!-- Roof (крыша) -->
  <link name="roof">
    <visual>
      <geometry>
        <box size="0.7 0.58 0.04"/>
      </geometry>
      <material name="red">
        <color rgba="0.9 0.15 0.1 1"/>
      </material>
    </visual>
    <collision>
      <geometry>
        <box size="0.7 0.58 0.04"/>
      </geometry>
    </collision>
    <inertial>
      <mass value="2.5"/>
      <origin xyz="0 0 0" rpy="0 0 0"/>
      <inertia ixx="0.2" ixy="0" ixz="0" iyy="0.4" iyz="0" izz="0.5"/>
    </inertial>
  </link>

  <joint name="roof_joint" type="fixed">
    <parent link="cabin"/>
    <child link="roof"/>
    <origin xyz="0 0 0.18" rpy="0 0 0"/>
  </joint>

  <!-- A-Pillar Left (передняя стойка) -->
  <link name="a_pillar_left">
    <visual>
      <geometry>
        <box size="0.04 0.04 0.25"/>
      </geometry>
      <material name="red">
        <color rgba="0.9 0.15 0.1 1"/>
      </material>
    </visual>
  </link>

  <joint name="a_pillar_left_joint" type="fixed">
    <parent link="cabin"/>
    <child link="a_pillar_left"/>
    <origin xyz="0.32 0.28 0.03" rpy="0 -0.3 0"/>
  </joint>

  <!-- A-Pillar Right -->
  <link name="a_pillar_right">
    <visual>
      <geometry>
        <box size="0.04 0.04 0.25"/>
      </geometry>
      <material name="red">
        <color rgba="0.9 0.15 0.1 1"/>
      </material>
    </visual>
  </link>

  <joint name="a_pillar_right_joint" type="fixed">
    <parent link="cabin"/>
    <child link="a_pillar_right"/>
    <origin xyz="0.32 -0.28 0.03" rpy="0 -0.3 0"/>
  </joint>

  <!-- C-Pillar Left (задняя стойка) -->
  <link name="c_pillar_left">
    <visual>
      <geometry>
        <box size="0.04 0.04 0.25"/>
      </geometry>
      <material name="red">
        <color rgba="0.9 0.15 0.1 1"/>
      </material>
    </visual>
  </link>

  <joint name="c_pillar_left_joint" type="fixed">
    <parent link="cabin"/>
    <child link="c_pillar_left"/>
    <origin xyz="-0.32 0.28 0.03" rpy="0 0.25 0"/>
  </joint>

  <!-- C-Pillar Right -->
  <link name="c_pillar_right">
    <visual>
      <geometry>
        <box size="0.04 0.04 0.25"/>
      </geometry>
      <material name="red">
        <color rgba="0.9 0.15 0.1 1"/>
      </material>
    </visual>
  </link>

  <joint name="c_pillar_right_joint" type="fixed">
    <parent link="cabin"/>
    <child link="c_pillar_right"/>
    <origin xyz="-0.32 -0.28 0.03" rpy="0 0.25 0"/>
  </joint>

  <!-- Trunk (багажник - характерный для Жигулей) -->
  <link name="trunk">
    <visual>
      <geometry>
        <box size="0.4 0.62 0.12"/>
      </geometry>
      <material name="red">
        <color rgba="0.9 0.15 0.1 1"/>
      </material>
    </visual>
    <collision>
      <geometry>
        <box size="0.4 0.62 0.12"/>
      </geometry>
    </collision>
    <inertial>
      <mass value="4.0"/>
      <origin xyz="0 0 0" rpy="0 0 0"/>
      <inertia ixx="0.4" ixy="0" ixz="0" iyy="0.7" iyz="0" izz="0.9"/>
    </inertial>
  </link>

  <joint name="trunk_joint" type="fixed">
    <parent link="base_link"/>
    <child link="trunk"/>
    <origin xyz="-0.6 0 0.12" rpy="0 -0.02 0"/>
  </joint>

  <!-- Trunk Lid Edge (кромка крышки багажника) -->
  <link name="trunk_lid">
    <visual>
      <geometry>
        <box size="0.35 0.58 0.02"/>
      </geometry>
      <material name="red">
        <color rgba="0.85 0.12 0.08 1"/>
      </material>
    </visual>
  </link>

  <joint name="trunk_lid_joint" type="fixed">
    <parent link="trunk"/>
    <child link="trunk_lid"/>
    <origin xyz="0 0 0.07" rpy="0 0 0"/>
  </joint>

  <!-- Windshield (лобовое стекло) -->
  <link name="windshield">
    <visual>
      <geometry>
        <box size="0.02 0.55 0.22"/>
      </geometry>
      <material name="glass">
        <color rgba="0.3 0.4 0.6 0.5"/>
      </material>
    </visual>
  </link>
  
  <joint name="windshield_joint" type="fixed">
    <parent link="cabin"/>
    <child link="windshield"/>
    <origin xyz="0.36 0 0.02" rpy="0 -0.25 0"/>
  </joint>

  <!-- Rear Window (заднее стекло) -->
  <link name="rear_window">
    <visual>
      <geometry>
        <box size="0.02 0.55 0.2"/>
      </geometry>
      <material name="glass">
        <color rgba="0.3 0.4 0.6 0.5"/>
      </material>
    </visual>
  </link>

  <joint name="rear_window_joint" type="fixed">
    <parent link="cabin"/>
    <child link="rear_window"/>
    <origin xyz="-0.36 0 0.0" rpy="0 0.22 0"/>
  </joint>

  <!-- Side Window Left -->
  <link name="side_window_left">
    <visual>
      <geometry>
        <box size="0.5 0.02 0.18"/>
      </geometry>
      <material name="glass">
        <color rgba="0.3 0.4 0.6 0.5"/>
      </material>
    </visual>
  </link>

  <joint name="side_window_left_joint" type="fixed">
    <parent link="cabin"/>
    <child link="side_window_left"/>
    <origin xyz="0 0.3 0.04" rpy="0 0 0"/>
  </joint>

  <!-- Side Window Right -->
  <link name="side_window_right">
    <visual>
      <geometry>
        <box size="0.5 0.02 0.18"/>
      </geometry>
      <material name="glass">
        <color rgba="0.3 0.4 0.6 0.5"/>
      </material>
    </visual>
  </link>

  <joint name="side_window_right_joint" type="fixed">
    <parent link="cabin"/>
    <child link="side_window_right"/>
    <origin xyz="0 -0.3 0.04" rpy="0 0 0"/>
  </joint>

  <!-- Grille (решётка радиатора - характерная для ВАЗ) -->
  <link name="grille">
    <visual>
      <geometry>
        <box size="0.03 0.35 0.1"/>
      </geometry>
      <material name="chrome">
        <color rgba="0.75 0.75 0.8 1"/>
      </material>
    </visual>
  </link>

  <joint name="grille_joint" type="fixed">
    <parent link="base_link"/>
    <child link="grille"/>
    <origin xyz="0.88 0 0.04" rpy="0 0 0"/>
  </joint>

  <!-- Grille Bars (горизонтальные полосы решётки) -->
  <link name="grille_bar1">
    <visual>
      <geometry>
        <box size="0.01 0.33 0.015"/>
      </geometry>
      <material name="black">
        <color rgba="0.1 0.1 0.1 1"/>
      </material>
    </visual>
  </link>

  <joint name="grille_bar1_joint" type="fixed">
    <parent link="grille"/>
    <child link="grille_bar1"/>
    <origin xyz="0.02 0 0.03" rpy="0 0 0"/>
  </joint>

  <link name="grille_bar2">
    <visual>
      <geometry>
        <box size="0.01 0.33 0.015"/>
      </geometry>
      <material name="black">
        <color rgba="0.1 0.1 0.1 1"/>
      </material>
    </visual>
  </link>

  <joint name="grille_bar2_joint" type="fixed">
    <parent link="grille"/>
    <child link="grille_bar2"/>
    <origin xyz="0.02 0 0" rpy="0 0 0"/>
  </joint>

  <link name="grille_bar3">
    <visual>
      <geometry>
        <box size="0.01 0.33 0.015"/>
      </geometry>
      <material name="black">
        <color rgba="0.1 0.1 0.1 1"/>
      </material>
    </visual>
  </link>

  <joint name="grille_bar3_joint" type="fixed">
    <parent link="grille"/>
    <child link="grille_bar3"/>
    <origin xyz="0.02 0 -0.03" rpy="0 0 0"/>
  </joint>

  <!-- Front Bumper (хромированный бампер) -->
  <link name="front_bumper">
    <visual>
      <geometry>
        <box size="0.08 0.68 0.08"/>
      </geometry>
      <material name="chrome">
        <color rgba="0.8 0.8 0.85 1"/>
      </material>
    </visual>
    <collision>
      <geometry>
        <box size="0.08 0.68 0.08"/>
      </geometry>
    </collision>
    <inertial>
      <mass value="2.5"/>
      <origin xyz="0 0 0" rpy="0 0 0"/>
      <inertia ixx="0.1" ixy="0" ixz="0" iyy="0.15" iyz="0" izz="0.15"/>
    </inertial>
  </link>

  <joint name="front_bumper_joint" type="fixed">
    <parent link="base_link"/>
    <child link="front_bumper"/>
    <origin xyz="0.94 0 -0.02" rpy="0 0 0"/>
  </joint>

  <!-- Front Bumper Corners -->
  <link name="front_bumper_left">
    <visual>
      <geometry>
        <box size="0.12 0.06 0.08"/>
      </geometry>
      <material name="chrome">
        <color rgba="0.8 0.8 0.85 1"/>
      </material>
    </visual>
  </link>

  <joint name="front_bumper_left_joint" type="fixed">
    <parent link="front_bumper"/>
    <child link="front_bumper_left"/>
    <origin xyz="-0.04 0.36 0" rpy="0 0 0.3"/>
  </joint>

  <link name="front_bumper_right">
    <visual>
      <geometry>
        <box size="0.12 0.06 0.08"/>
      </geometry>
      <material name="chrome">
        <color rgba="0.8 0.8 0.85 1"/>
      </material>
    </visual>
  </link>

  <joint name="front_bumper_right_joint" type="fixed">
    <parent link="front_bumper"/>
    <child link="front_bumper_right"/>
    <origin xyz="-0.04 -0.36 0" rpy="0 0 -0.3"/>
  </joint>

  <!-- Rear Bumper -->
  <link name="rear_bumper">
    <visual>
      <geometry>
        <box size="0.08 0.68 0.08"/>
      </geometry>
      <material name="chrome">
        <color rgba="0.8 0.8 0.85 1"/>
      </material>
    </visual>
    <collision>
      <geometry>
        <box size="0.08 0.68 0.08"/>
      </geometry>
    </collision>
    <inertial>
      <mass value="2.5"/>
      <origin xyz="0 0 0" rpy="0 0 0"/>
      <inertia ixx="0.1" ixy="0" ixz="0" iyy="0.15" iyz="0" izz="0.15"/>
    </inertial>
  </link>

  <joint name="rear_bumper_joint" type="fixed">
    <parent link="base_link"/>
    <child link="rear_bumper"/>
    <origin xyz="-0.94 0 -0.02" rpy="0 0 0"/>
  </joint>

  <!-- Rear Bumper Corners -->
  <link name="rear_bumper_left">
    <visual>
      <geometry>
        <box size="0.12 0.06 0.08"/>
      </geometry>
      <material name="chrome">
        <color rgba="0.8 0.8 0.85 1"/>
      </material>
    </visual>
  </link>

  <joint name="rear_bumper_left_joint" type="fixed">
    <parent link="rear_bumper"/>
    <child link="rear_bumper_left"/>
    <origin xyz="0.04 0.36 0" rpy="0 0 -0.3"/>
  </joint>

  <link name="rear_bumper_right">
    <visual>
      <geometry>
        <box size="0.12 0.06 0.08"/>
      </geometry>
      <material name="chrome">
        <color rgba="0.8 0.8 0.85 1"/>
      </material>
    </visual>
  </link>

  <joint name="rear_bumper_right_joint" type="fixed">
    <parent link="rear_bumper"/>
    <child link="rear_bumper_right"/>
    <origin xyz="0.04 -0.36 0" rpy="0 0 0.3"/>
  </joint>

  <!-- Side Mirror Left (боковое зеркало) -->
  <link name="mirror_left">
    <visual>
      <geometry>
        <box size="0.08 0.02 0.06"/>
      </geometry>
      <material name="chrome">
        <color rgba="0.8 0.8 0.85 1"/>
      </material>
    </visual>
  </link>

  <joint name="mirror_left_joint" type="fixed">
    <parent link="cabin"/>
    <child link="mirror_left"/>
    <origin xyz="0.25 0.35 -0.05" rpy="0 0 0"/>
  </joint>

  <!-- Side Mirror Right -->
  <link name="mirror_right">
    <visual>
      <geometry>
        <box size="0.08 0.02 0.06"/>
      </geometry>
      <material name="chrome">
        <color rgba="0.8 0.8 0.85 1"/>
      </material>
    </visual>
  </link>

  <joint name="mirror_right_joint" type="fixed">
    <parent link="cabin"/>
    <child link="mirror_right"/>
    <origin xyz="0.25 -0.35 -0.05" rpy="0 0 0"/>
  </joint>

  <!-- Door Handles -->
  <link name="door_handle_left">
    <visual>
      <geometry>
        <box size="0.08 0.015 0.02"/>
      </geometry>
      <material name="chrome">
        <color rgba="0.8 0.8 0.85 1"/>
      </material>
    </visual>
  </link>

  <joint name="door_handle_left_joint" type="fixed">
    <parent link="cabin"/>
    <child link="door_handle_left"/>
    <origin xyz="0.1 0.31 -0.08" rpy="0 0 0"/>
  </joint>

  <link name="door_handle_right">
    <visual>
      <geometry>
        <box size="0.08 0.015 0.02"/>
      </geometry>
      <material name="chrome">
        <color rgba="0.8 0.8 0.85 1"/>
      </material>
    </visual>
  </link>

  <joint name="door_handle_right_joint" type="fixed">
    <parent link="cabin"/>
    <child link="door_handle_right"/>
    <origin xyz="0.1 -0.31 -0.08" rpy="0 0 0"/>
  </joint>

  <!-- Left Front Wheel -->
  <link name="left_front_wheel">
    <visual>
      <geometry>
        <cylinder length="0.1" radius="0.15"/>
      </geometry>
      <origin rpy="1.5708 0 0" xyz="0 0 0"/>
      <material name="dark_gray">
        <color rgba="0.2 0.2 0.2 1"/>
      </material>
    </visual>
    <collision>
      <geometry>
        <cylinder length="0.1" radius="0.15"/>
      </geometry>
      <origin rpy="1.5708 0 0" xyz="0 0 0"/>
    </collision>
    <inertial>
      <mass value="2.0"/>
      <origin xyz="0 0 0" rpy="0 0 0"/>
      <inertia ixx="0.02" ixy="0" ixz="0" iyy="0.02" iyz="0" izz="0.03"/>
    </inertial>
  </link>

  <!-- Wheel Hub Left Front (колпак колеса) -->
  <link name="hub_lf">
    <visual>
      <geometry>
        <cylinder length="0.02" radius="0.08"/>
      </geometry>
      <origin rpy="1.5708 0 0" xyz="0 0.06 0"/>
      <material name="chrome">
        <color rgba="0.75 0.75 0.8 1"/>
      </material>
    </visual>
  </link>

  <joint name="hub_lf_joint" type="fixed">
    <parent link="left_front_wheel"/>
    <child link="hub_lf"/>
    <origin xyz="0 0 0" rpy="0 0 0"/>
  </joint>

  <joint name="left_front_wheel_joint" type="continuous">
    <parent link="base_link"/>
    <child link="left_front_wheel"/>
    <origin xyz="0.55 0.38 -0.12" rpy="0 0 0"/>
    <axis xyz="0 1 0"/>
    <dynamics damping="0.1" friction="0.1"/>
  </joint>

  <!-- Right Front Wheel -->
  <link name="right_front_wheel">
    <visual>
      <geometry>
        <cylinder length="0.1" radius="0.15"/>
      </geometry>
      <origin rpy="1.5708 0 0" xyz="0 0 0"/>
      <material name="dark_gray">
        <color rgba="0.2 0.2 0.2 1"/>
      </material>
    </visual>
    <collision>
      <geometry>
        <cylinder length="0.1" radius="0.15"/>
      </geometry>
      <origin rpy="1.5708 0 0" xyz="0 0 0"/>
    </collision>
    <inertial>
      <mass value="2.0"/>
      <origin xyz="0 0 0" rpy="0 0 0"/>
      <inertia ixx="0.02" ixy="0" ixz="0" iyy="0.02" iyz="0" izz="0.03"/>
    </inertial>
  </link>

  <!-- Wheel Hub Right Front -->
  <link name="hub_rf">
    <visual>
      <geometry>
        <cylinder length="0.02" radius="0.08"/>
      </geometry>
      <origin rpy="1.5708 0 0" xyz="0 -0.06 0"/>
      <material name="chrome">
        <color rgba="0.75 0.75 0.8 1"/>
      </material>
    </visual>
  </link>

  <joint name="hub_rf_joint" type="fixed">
    <parent link="right_front_wheel"/>
    <child link="hub_rf"/>
    <origin xyz="0 0 0" rpy="0 0 0"/>
  </joint>

  <joint name="right_front_wheel_joint" type="continuous">
    <parent link="base_link"/>
    <child link="right_front_wheel"/>
    <origin xyz="0.55 -0.38 -0.12" rpy="0 0 0"/>
    <axis xyz="0 1 0"/>
    <dynamics damping="0.1" friction="0.1"/>
  </joint>

  <!-- Left Rear Wheel -->
  <link name="left_rear_wheel">
    <visual>
      <geometry>
        <cylinder length="0.1" radius="0.15"/>
      </geometry>
      <origin rpy="1.5708 0 0" xyz="0 0 0"/>
      <material name="dark_gray">
        <color rgba="0.2 0.2 0.2 1"/>
      </material>
    </visual>
    <collision>
      <geometry>
        <cylinder length="0.1" radius="0.15"/>
      </geometry>
      <origin rpy="1.5708 0 0" xyz="0 0 0"/>
    </collision>
    <inertial>
      <mass value="2.0"/>
      <origin xyz="0 0 0" rpy="0 0 0"/>
      <inertia ixx="0.02" ixy="0" ixz="0" iyy="0.02" iyz="0" izz="0.03"/>
    </inertial>
  </link>

  <!-- Wheel Hub Left Rear -->
  <link name="hub_lr">
    <visual>
      <geometry>
        <cylinder length="0.02" radius="0.08"/>
      </geometry>
      <origin rpy="1.5708 0 0" xyz="0 0.06 0"/>
      <material name="chrome">
        <color rgba="0.75 0.75 0.8 1"/>
      </material>
    </visual>
  </link>

  <joint name="hub_lr_joint" type="fixed">
    <parent link="left_rear_wheel"/>
    <child link="hub_lr"/>
    <origin xyz="0 0 0" rpy="0 0 0"/>
  </joint>

  <joint name="left_rear_wheel_joint" type="continuous">
    <parent link="base_link"/>
    <child link="left_rear_wheel"/>
    <origin xyz="-0.55 0.38 -0.12" rpy="0 0 0"/>
    <axis xyz="0 1 0"/>
    <dynamics damping="0.02" friction="0.02"/>
  </joint>

  <!-- Right Rear Wheel -->
  <link name="right_rear_wheel">
    <visual>
      <geometry>
        <cylinder length="0.1" radius="0.15"/>
      </geometry>
      <origin rpy="1.5708 0 0" xyz="0 0 0"/>
      <material name="dark_gray">
        <color rgba="0.2 0.2 0.2 1"/>
      </material>
    </visual>
    <collision>
      <geometry>
        <cylinder length="0.1" radius="0.15"/>
      </geometry>
      <origin rpy="1.5708 0 0" xyz="0 0 0"/>
    </collision>
    <inertial>
      <mass value="2.0"/>
      <origin xyz="0 0 0" rpy="0 0 0"/>
      <inertia ixx="0.02" ixy="0" ixz="0" iyy="0.02" iyz="0" izz="0.03"/>
    </inertial>
  </link>

  <!-- Wheel Hub Right Rear -->
  <link name="hub_rr">
    <visual>
      <geometry>
        <cylinder length="0.02" radius="0.08"/>
      </geometry>
      <origin rpy="1.5708 0 0" xyz="0 -0.06 0"/>
      <material name="chrome">
        <color rgba="0.75 0.75 0.8 1"/>
      </material>
    </visual>
  </link>

  <joint name="hub_rr_joint" type="fixed">
    <parent link="right_rear_wheel"/>
    <child link="hub_rr"/>
    <origin xyz="0 0 0" rpy="0 0 0"/>
  </joint>

  <joint name="right_rear_wheel_joint" type="continuous">
    <parent link="base_link"/>
    <child link="right_rear_wheel"/>
    <origin xyz="-0.55 -0.38 -0.12" rpy="0 0 0"/>
    <axis xyz="0 1 0"/>
    <dynamics damping="0.02" friction="0.02"/>
  </joint>

  <!-- Front Lights (круглые фары - характерная черта Жигулей) -->
  <link name="left_headlight">
    <visual>
      <geometry>
        <cylinder length="0.04" radius="0.07"/>
      </geometry>
      <origin rpy="0 1.5708 0" xyz="0 0 0"/>
      <material name="yellow">
        <color rgba="1.0 0.95 0.6 1"/>
      </material>
    </visual>
    <collision>
      <geometry>
        <cylinder length="0.04" radius="0.07"/>
      </geometry>
      <origin rpy="0 1.5708 0" xyz="0 0 0"/>
    </collision>
    <inertial>
      <mass value="0.4"/>
      <origin xyz="0 0 0" rpy="0 0 0"/>
      <inertia ixx="0.005" ixy="0" ixz="0" iyy="0.005" iyz="0" izz="0.005"/>
    </inertial>
  </link>

  <joint name="left_headlight_joint" type="fixed">
    <parent link="base_link"/>
    <child link="left_headlight"/>
    <origin xyz="0.88 0.2 0.04" rpy="0 0 0"/>
  </joint>

  <!-- Headlight Chrome Ring Left -->
  <link name="headlight_ring_left">
    <visual>
      <geometry>
        <cylinder length="0.01" radius="0.075"/>
      </geometry>
      <origin rpy="0 1.5708 0" xyz="0.025 0 0"/>
      <material name="chrome">
        <color rgba="0.8 0.8 0.85 1"/>
      </material>
    </visual>
  </link>

  <joint name="headlight_ring_left_joint" type="fixed">
    <parent link="left_headlight"/>
    <child link="headlight_ring_left"/>
    <origin xyz="0 0 0" rpy="0 0 0"/>
  </joint>

  <link name="right_headlight">
    <visual>
      <geometry>
        <cylinder length="0.04" radius="0.07"/>
      </geometry>
      <origin rpy="0 1.5708 0" xyz="0 0 0"/>
      <material name="yellow">
        <color rgba="1.0 0.95 0.6 1"/>
      </material>
    </visual>
    <collision>
      <geometry>
        <cylinder length="0.04" radius="0.07"/>
      </geometry>
      <origin rpy="0 1.5708 0" xyz="0 0 0"/>
    </collision>
    <inertial>
      <mass value="0.4"/>
      <origin xyz="0 0 0" rpy="0 0 0"/>
      <inertia ixx="0.005" ixy="0" ixz="0" iyy="0.005" iyz="0" izz="0.005"/>
    </inertial>
  </link>

  <joint name="right_headlight_joint" type="fixed">
    <parent link="base_link"/>
    <child link="right_headlight"/>
    <origin xyz="0.88 -0.2 0.04" rpy="0 0 0"/>
  </joint>

  <!-- Headlight Chrome Ring Right -->
  <link name="headlight_ring_right">
    <visual>
      <geometry>
        <cylinder length="0.01" radius="0.075"/>
      </geometry>
      <origin rpy="0 1.5708 0" xyz="0.025 0 0"/>
      <material name="chrome">
        <color rgba="0.8 0.8 0.85 1"/>
      </material>
    </visual>
  </link>

  <joint name="headlight_ring_right_joint" type="fixed">
    <parent link="right_headlight"/>
    <child link="headlight_ring_right"/>
    <origin xyz="0 0 0" rpy="0 0 0"/>
  </joint>

  <!-- Turn Signals Front -->
  <link name="turn_signal_left">
    <visual>
      <geometry>
        <cylinder length="0.02" radius="0.03"/>
      </geometry>
      <origin rpy="0 1.5708 0" xyz="0 0 0"/>
      <material name="orange">
        <color rgba="1.0 0.6 0.1 1"/>
      </material>
    </visual>
  </link>

  <joint name="turn_signal_left_joint" type="fixed">
    <parent link="front_bumper"/>
    <child link="turn_signal_left"/>
    <origin xyz="-0.02 0.25 0.02" rpy="0 0 0"/>
  </joint>

  <link name="turn_signal_right">
    <visual>
      <geometry>
        <cylinder length="0.02" radius="0.03"/>
      </geometry>
      <origin rpy="0 1.5708 0" xyz="0 0 0"/>
      <material name="orange">
        <color rgba="1.0 0.6 0.1 1"/>
      </material>
    </visual>
  </link>

  <joint name="turn_signal_right_joint" type="fixed">
    <parent link="front_bumper"/>
    <child link="turn_signal_right"/>
    <origin xyz="-0.02 -0.25 0.02" rpy="0 0 0"/>
  </joint>

  <!-- Rear Lights (характерные прямоугольные) -->
  <link name="left_taillight">
    <visual>
      <geometry>
        <box size="0.03 0.12 0.06"/>
      </geometry>
      <material name="red_light">
        <color rgba="0.9 0.0 0.0 1"/>
      </material>
    </visual>
    <collision>
      <geometry>
        <box size="0.03 0.12 0.06"/>
      </geometry>
    </collision>
    <inertial>
      <mass value="0.3"/>
      <origin xyz="0 0 0" rpy="0 0 0"/>
      <inertia ixx="0.005" ixy="0" ixz="0" iyy="0.005" iyz="0" izz="0.005"/>
    </inertial>
  </link>

  <joint name="left_taillight_joint" type="fixed">
    <parent link="base_link"/>
    <child link="left_taillight"/>
    <origin xyz="-0.88 0.24 0.04" rpy="0 0 0"/>
  </joint>

  <link name="right_taillight">
    <visual>
      <geometry>
        <box size="0.03 0.12 0.06"/>
      </geometry>
      <material name="red_light">
        <color rgba="0.9 0.0 0.0 1"/>
      </material>
    </visual>
    <collision>
      <geometry>
        <box size="0.03 0.12 0.06"/>
      </geometry>
    </collision>
    <inertial>
      <mass value="0.3"/>
      <origin xyz="0 0 0" rpy="0 0 0"/>
      <inertia ixx="0.005" ixy="0" ixz="0" iyy="0.005" iyz="0" izz="0.005"/>
    </inertial>
  </link>

  <joint name="right_taillight_joint" type="fixed">
    <parent link="base_link"/>
    <child link="right_taillight"/>
    <origin xyz="-0.88 -0.24 0.04" rpy="0 0 0"/>
  </joint>

  <!-- License Plate Rear -->
  <link name="license_plate_rear">
    <visual>
      <geometry>
        <box size="0.01 0.2 0.05"/>
      </geometry>
      <material name="white">
        <color rgba="1.0 1.0 1.0 1"/>
      </material>
    </visual>
  </link>

  <joint name="license_plate_rear_joint" type="fixed">
    <parent link="rear_bumper"/>
    <child link="license_plate_rear"/>
    <origin xyz="0.045 0 0.02" rpy="0 0 0"/>
  </joint>

  <!-- License Plate Front -->
  <link name="license_plate_front">
    <visual>
      <geometry>
        <box size="0.01 0.2 0.05"/>
      </geometry>
      <material name="white">
        <color rgba="1.0 1.0 1.0 1"/>
      </material>
    </visual>
  </link>

  <joint name="license_plate_front_joint" type="fixed">
    <parent link="front_bumper"/>
    <child link="license_plate_front"/>
    <origin xyz="-0.045 0 0.02" rpy="0 0 0"/>
  </joint>

  <!-- Gazebo Plugins -->
  
  <!-- Differential Drive Plugin for Gazebo Harmonic -->
  <gazebo>
    <plugin filename="gz-sim-diff-drive-system" name="gz::sim::systems::DiffDrive">
      <left_joint>left_rear_wheel_joint</left_joint>
      <right_joint>right_rear_wheel_joint</right_joint>
      <wheel_separation>0.76</wheel_separation>
      <wheel_radius>0.15</wheel_radius>
      <odom_publish_frequency>50</odom_publish_frequency>
      <topic>cmd_vel</topic>
      <odom_topic>odom</odom_topic>
      <frame_id>odom</frame_id>
      <child_frame_id>base_link</child_frame_id>
      <max_linear_acceleration>8.0</max_linear_acceleration>
      <min_linear_acceleration>-8.0</min_linear_acceleration>
      <max_angular_acceleration>10.0</max_angular_acceleration>
      <min_angular_acceleration>-10.0</min_angular_acceleration>
      <max_linear_velocity>8.0</max_linear_velocity>
      <min_linear_velocity>-8.0</min_linear_velocity>
      <max_angular_velocity>6.0</max_angular_velocity>
      <min_angular_velocity>-6.0</min_angular_velocity>
      <tf_topic>/tf</tf_topic>
    </plugin>
  </gazebo>

  <!-- Joint State Publisher Plugin -->
  <gazebo>
    <plugin filename="gz-sim-joint-state-publisher-system" name="gz::sim::systems::JointStatePublisher">
      <joint_name>left_front_wheel_joint</joint_name>
      <joint_name>right_front_wheel_joint</joint_name>
      <joint_name>left_rear_wheel_joint</joint_name>
      <joint_name>right_rear_wheel_joint</joint_name>
    </plugin>
  </gazebo>

  <!-- Pose Publisher Plugin -->
  <gazebo>
    <plugin filename="gz-sim-pose-publisher-system" name="gz::sim::systems::PosePublisher">
      <publish_link_pose>true</publish_link_pose>
      <publish_sensor_pose>true</publish_sensor_pose>
      <publish_collision_pose>false</publish_collision_pose>
      <publish_visual_pose>false</publish_visual_pose>
      <publish_nested_model_pose>true</publish_nested_model_pose>
      <update_frequency>50</update_frequency>
    </plugin>
  </gazebo>

  <!-- Gazebo material properties -->
  <gazebo reference="base_link">
    <material>Gazebo/Red</material>
  </gazebo>

  <gazebo reference="hood">
    <material>Gazebo/Red</material>
  </gazebo>

  <gazebo reference="hood_ridge">
    <material>Gazebo/Red</material>
  </gazebo>

  <gazebo reference="front_fender_left">
    <material>Gazebo/Red</material>
  </gazebo>

  <gazebo reference="front_fender_right">
    <material>Gazebo/Red</material>
  </gazebo>

  <gazebo reference="rear_fender_left">
    <material>Gazebo/Red</material>
  </gazebo>

  <gazebo reference="rear_fender_right">
    <material>Gazebo/Red</material>
  </gazebo>

  <gazebo reference="cabin">
    <material>Gazebo/BlueTransparent</material>
  </gazebo>

  <gazebo reference="roof">
    <material>Gazebo/Red</material>
  </gazebo>

  <gazebo reference="a_pillar_left">
    <material>Gazebo/Red</material>
  </gazebo>

  <gazebo reference="a_pillar_right">
    <material>Gazebo/Red</material>
  </gazebo>

  <gazebo reference="c_pillar_left">
    <material>Gazebo/Red</material>
  </gazebo>

  <gazebo reference="c_pillar_right">
    <material>Gazebo/Red</material>
  </gazebo>

  <gazebo reference="trunk">
    <material>Gazebo/Red</material>
  </gazebo>

  <gazebo reference="trunk_lid">
    <material>Gazebo/Red</material>
  </gazebo>

  <gazebo reference="grille">
    <material>Gazebo/Chrome</material>
  </gazebo>

  <gazebo reference="front_bumper">
    <material>Gazebo/Chrome</material>
  </gazebo>

  <gazebo reference="front_bumper_left">
    <material>Gazebo/Chrome</material>
  </gazebo>

  <gazebo reference="front_bumper_right">
    <material>Gazebo/Chrome</material>
  </gazebo>

  <gazebo reference="rear_bumper">
    <material>Gazebo/Chrome</material>
  </gazebo>

  <gazebo reference="rear_bumper_left">
    <material>Gazebo/Chrome</material>
  </gazebo>

  <gazebo reference="rear_bumper_right">
    <material>Gazebo/Chrome</material>
  </gazebo>

  <gazebo reference="mirror_left">
    <material>Gazebo/Chrome</material>
  </gazebo>

  <gazebo reference="mirror_right">
    <material>Gazebo/Chrome</material>
  </gazebo>

  <!-- Front wheels - low friction for turning -->
  <gazebo reference="left_front_wheel">
    <material>Gazebo/DarkGrey</material>
    <mu1>0.2</mu1>
    <mu2>0.2</mu2>
    <kp>1000000.0</kp>
    <kd>100.0</kd>
    <minDepth>0.001</minDepth>
  </gazebo>

  <gazebo reference="right_front_wheel">
    <material>Gazebo/DarkGrey</material>
    <mu1>0.2</mu1>
    <mu2>0.2</mu2>
    <kp>1000000.0</kp>
    <kd>100.0</kd>
    <minDepth>0.001</minDepth>
  </gazebo>

  <!-- Rear wheels - Drift setup (Corrected with fdir1) -->
  <gazebo reference="left_rear_wheel">
    <material>Gazebo/DarkGrey</material>
    <mu1>2.0</mu1>
    <mu2>0.1</mu2>
    <fdir1>1 0 0</fdir1>
    <kp>1000000.0</kp>
    <kd>100.0</kd>
    <minDepth>0.001</minDepth>
  </gazebo>

  <gazebo reference="right_rear_wheel">
    <material>Gazebo/DarkGrey</material>
    <mu1>2.0</mu1>
    <mu2>0.1</mu2>
    <fdir1>1 0 0</fdir1>
    <kp>1000000.0</kp>
    <kd>100.0</kd>
    <minDepth>0.001</minDepth>
  </gazebo>

  <gazebo reference="left_headlight">
    <material>Gazebo/Yellow</material>
  </gazebo>

  <gazebo reference="right_headlight">
    <material>Gazebo/Yellow</material>
  </gazebo>

  <gazebo reference="headlight_ring_left">
    <material>Gazebo/Chrome</material>
  </gazebo>

  <gazebo reference="headlight_ring_right">
    <material>Gazebo/Chrome</material>
  </gazebo>

  <gazebo reference="turn_signal_left">
    <material>Gazebo/Orange</material>
  </gazebo>

  <gazebo reference="turn_signal_right">
    <material>Gazebo/Orange</material>
  </gazebo>

  <gazebo reference="left_taillight">
    <material>Gazebo/Red</material>
  </gazebo>

  <gazebo reference="right_taillight">
    <material>Gazebo/Red</material>
  </gazebo>

  <gazebo reference="hub_lf">
    <material>Gazebo/Chrome</material>
  </gazebo>

  <gazebo reference="hub_rf">
    <material>Gazebo/Chrome</material>
  </gazebo>

  <gazebo reference="hub_lr">
    <material>Gazebo/Chrome</material>
  </gazebo>

  <gazebo reference="hub_rr">
    <material>Gazebo/Chrome</material>
  </gazebo>

  <gazebo reference="license_plate_front">
    <material>Gazebo/White</material>
  </gazebo>

  <gazebo reference="license_plate_rear">
    <material>Gazebo/White</material>
  </gazebo>

  <!-- Lidar Link -->
  <link name="lidar_link">
    <visual>
      <geometry>
        <cylinder radius="0.05" length="0.04"/>
      </geometry>
      <material name="black">
        <color rgba="0 0 0 1"/>
      </material>
    </visual>
    <collision>
      <geometry>
        <cylinder radius="0.05" length="0.04"/>
      </geometry>
    </collision>
    <inertial>
      <mass value="0.1"/>
      <origin xyz="0 0 0" rpy="0 0 0"/>
      <inertia ixx="0.0001" ixy="0" ixz="0" iyy="0.0001" iyz="0" izz="0.0001"/>
    </inertial>
  </link>

  <joint name="lidar_joint" type="fixed">
    <parent link="roof"/>
    <child link="lidar_link"/>
    <origin xyz="0 0 0.08" rpy="0 0 0"/>
  </joint>

  <gazebo reference="lidar_link">
    <sensor name="gpu_lidar" type="gpu_lidar">
      <pose>0 0 0 0 0 0</pose>
      <topic>scan</topic>
      <frame_id>lidar_link</frame_id>
      <ignition_frame_id>lidar_link</ignition_frame_id>
      <update_rate>10</update_rate>
      <ray>
        <scan>
          <horizontal>
            <samples>640</samples>
            <resolution>1</resolution>
            <min_angle>-3.14159</min_angle>
            <max_angle>3.14159</max_angle>
          </horizontal>
          <vertical>
            <samples>1</samples>
            <resolution>1</resolution>
            <min_angle>0</min_angle>
            <max_angle>0</max_angle>
          </vertical>
        </scan>
        <range>
          <min>0.08</min>
          <max>10.0</max>
          <resolution>0.01</resolution>
        </range>
      </ray>
      <always_on>1</always_on>
      <visualize>true</visualize>
    </sensor>
  </gazebo>

  <!-- Depth Camera Link -->
  <link name="camera_link">
    <visual>
      <geometry>
        <box size="0.02 0.1 0.02"/>
      </geometry>
      <material name="black">
        <color rgba="0 0 0 1"/>
      </material>
    </visual>
    <collision>
      <geometry>
        <box size="0.02 0.1 0.02"/>
      </geometry>
    </collision>
    <inertial>
      <mass value="0.05"/>
      <origin xyz="0 0 0" rpy="0 0 0"/>
      <inertia ixx="0.0001" ixy="0" ixz="0" iyy="0.0001" iyz="0" izz="0.0001"/>
    </inertial>
  </link>

  <joint name="camera_joint" type="fixed">
    <parent link="roof"/>
    <child link="camera_link"/>
    <origin xyz="0.3 0 0.04" rpy="0 0 0"/>
  </joint>

  <gazebo reference="camera_link">
    <sensor name="depth_camera" type="depth_camera">
      <pose>0 0 0 0 0 0</pose>
      <topic>depth_camera</topic>
      <frame_id>camera_link</frame_id>
      <ignition_frame_id>camera_link</ignition_frame_id>
      <update_rate>6</update_rate>
      <always_on>1</always_on>
      <camera>
        <horizontal_fov>1.51843645</horizontal_fov>
        <image>
          <width>848</width>
          <height>480</height>
          <format>R_FLOAT32</format>
        </image>
        <clip>
          <near>0.1</near>
          <far>10</far>
        </clip>
        <lens>
          <intrinsics>
            <fx>421.61578369140625</fx>
            <fy>421.61578369140625</fy>
            <cx>422.2854309082031</cx>
            <cy>236.57237243652344</cy>
            <s>0</s>
          </intrinsics>
        </lens>
      </camera>
      <visualize>true</visualize>
    </sensor>
  </gazebo>

  <!-- IMU Link -->
  <link name="imu_link">
    <visual>
      <geometry>
        <box size="0.05 0.05 0.02"/>
      </geometry>
      <material name="black">
        <color rgba="0 0 0 1"/>
      </material>
    </visual>
    <collision>
      <geometry>
        <box size="0.05 0.05 0.02"/>
      </geometry>
    </collision>
    <inertial>
      <mass value="0.05"/>
      <origin xyz="0 0 0" rpy="0 0 0"/>
      <inertia ixx="0.0001" ixy="0" ixz="0" iyy="0.0001" iyz="0" izz="0.0001"/>
    </inertial>
  </link>

  <joint name="imu_joint" type="fixed">
    <parent link="base_link"/>
    <child link="imu_link"/>
    <origin xyz="0 0 0.15" rpy="0 0 0"/>
  </joint>

  <gazebo reference="imu_link">
    <sensor name="imu_sensor" type="imu">
      <pose>0 0 0 0 0 0</pose>
      <topic>imu</topic>
      <frame_id>imu_link</frame_id>
      <ignition_frame_id>imu_link</ignition_frame_id>
      <update_rate>100</update_rate>
      <always_on>1</always_on>
      <visualize>true</visualize>
      <imu>
        <angular_velocity>
          <x>
            <noise type="gaussian">
              <mean>0.0</mean>
              <stddev>2e-4</stddev>
            </noise>
          </x>
          <y>
            <noise type="gaussian">
              <mean>0.0</mean>
              <stddev>2e-4</stddev>
            </noise>
          </y>
          <z>
            <noise type="gaussian">
              <mean>0.0</mean>
              <stddev>2e-4</stddev>
            </noise>
          </z>
        </angular_velocity>
        <linear_acceleration>
          <x>
            <noise type="gaussian">
              <mean>0.0</mean>
              <stddev>1.7e-2</stddev>
            </noise>
          </x>
          <y>
            <noise type="gaussian">
              <mean>0.0</mean>
              <stddev>1.7e-2</stddev>
            </noise>
          </y>
          <z>
            <noise type="gaussian">
              <mean>0.0</mean>
              <stddev>1.7e-2</stddev>
            </noise>
          </z>
        </linear_acceleration>
      </imu>
    </sensor>
  </gazebo>

</robot>
